<?xml version="1.0" encoding="utf-8"?>
<!-- This URDF was automatically created by SolidWorks to URDF Exporter! Originally created by Stephen Brawner (brawner@gmail.com) 
     Commit Version: 1.5.1-0-g916b5db  Build Version: 1.5.7152.31018
     For more information, please see http://wiki.ros.org/sw_urdf_exporter -->
<robot
  name="Marvin.urdf">
  <link
    name="Base_L">
    <inertial>
      <origin
        xyz="0.00032267 4.798E-05 0.04066353"
        rpy="0 0 0" />
      <mass
        value="1.1962" />
      <inertia
        ixx="0.00107329"
        ixy="-1.68E-06"
        ixz="-1.05E-05"
        iyy="0.00107003"
        iyz="-3.43E-06"
        izz="0.00127315" />
    </inertial>
    <visual>
      <origin
        xyz="0 0 0"
        rpy="0 0 0" />
      <geometry>
        <mesh
          filename="package://Marvin M6-S-L-CCS-696-V4.0_URDF/meshes/Base_L.STL" />
      </geometry>
      <material
        name="">
        <color
          rgba="1 0 0 1" />
      </material>
    </visual>
    <collision>
      <origin
        xyz="0 0 0"
        rpy="0 0 0" />
      <geometry>
        <mesh
          filename="package://Marvin M6-S-L-CCS-696-V4.0_URDF/meshes/Base_L.STL" />
      </geometry>
    </collision>
  </link>
  <link
    name="Link1_L">
    <inertial>
      <origin
        xyz="0.00002347 0.00557150 -0.03075998"
        rpy="0 0 0" />
      <mass
        value="1.9705" />
      <inertia
        ixx="0.00492293"
        ixy="0.00000550"
        ixz="0.00000193"
        iyy="0.00526513"
        iyz="0.00033232"
        izz="0.00188107" />
    </inertial>
    <visual>
      <origin
        xyz="0 0 0"
        rpy="0 0 0" />
      <geometry>
        <mesh
          filename="package://Marvin M6-S-L-CCS-696-V4.0_URDF/meshes/Link1_L.STL" />
      </geometry>
      <material
        name="">
        <color
          rgba="0 1 0 1" />
      </material>
    </visual>
    <collision>
      <origin
        xyz="0 0 0"
        rpy="0 0 0" />
      <geometry>
        <mesh
          filename="package://Marvin M6-S-L-CCS-696-V4.0_URDF/meshes/Link1_L.STL" />
      </geometry>
    </collision>
  </link>
  <joint
    name="Joint1_L"
    type="revolute">
    <origin
      xyz="0 0 0.1745"
      rpy="0 0 0" />
    <parent
      link="Base_L" />
    <child
      link="Link1_L" />
    <axis
      xyz="0 0 1" />
    <limit
      lower="-3.1067"
      upper="3.1067"
      effort="108"
      velocity="3.1416" />
  </joint>
  <link
    name="Link2_L">
    <inertial>
      <origin
        xyz="0.00013483 0.06170460 0.00950639"
        rpy="0 0 0" />
      <mass
        value="2.24398" />
      <inertia
        ixx="0.01194933"
        ixy="0.00000336"
        ixz="0.00000091"
        iyy="0.00361581"
        iyz="-0.00132804"
        izz="0.01098356" />
    </inertial>
    <visual>
      <origin
        xyz="0 0 0"
        rpy="0 0 0" />
      <geometry>
        <mesh
          filename="package://Marvin M6-S-L-CCS-696-V4.0_URDF/meshes/Link2_L.STL" />
      </geometry>
      <material
        name="">
        <color
          rgba="0 0 1 1" />
      </material>
    </visual>
    <collision>
      <origin
        xyz="0 0 0"
        rpy="0 0 0" />
      <geometry>
        <mesh
          filename="package://Marvin M6-S-L-CCS-696-V4.0_URDF/meshes/Link2_L.STL" />
      </geometry>
    </collision>
  </link>
  <joint
    name="Joint2_L"
    type="revolute">
    <origin
      xyz="0 0 0"
      rpy="1.5708 0 0" />
    <parent
      link="Link1_L" />
    <child
      link="Link2_L" />
    <axis
      xyz="0 0 1" />
    <limit
      lower="-2.0944"
      upper="2.0944"
      effort="108"
      velocity="3.1416" />
  </joint>
  <link
    name="Link3_L">
    <inertial>
      <origin
        xyz="0.00968562 0.00246599 -0.04627302"
        rpy="0 0 0" />
      <mass
        value="1.9242" />
      <inertia
        ixx="0.00718224"
        ixy="0.00004413"
        ixz="0.00089552"
        iyy="0.00762563"
        iyz="0.00022096"
        izz="0.00178597" />
    </inertial>
    <visual>
      <origin
        xyz="0 0 0"
        rpy="0 0 0" />
      <geometry>
        <mesh
          filename="package://Marvin M6-S-L-CCS-696-V4.0_URDF/meshes/Link3_L.STL" />
      </geometry>
      <material
        name="">
        <color
          rgba="1 0 0 1" />
      </material>
    </visual>
    <collision>
      <origin
        xyz="0 0 0"
        rpy="0 0 0" />
      <geometry>
        <mesh
          filename="package://Marvin M6-S-L-CCS-696-V4.0_URDF/meshes/Link3_L.STL" />
      </geometry>
    </collision>
  </link>
  <joint
    name="Joint3_L"
    type="revolute">
    <origin
      xyz="0 0.287 0"
      rpy="-1.5708 0 0" />
    <parent
      link="Link2_L" />
    <child
      link="Link3_L" />
    <axis
      xyz="0 0 1" />
    <limit
      lower="-3.1067"
      upper="3.1067"
      effort="66"
      velocity="3.1416" />
  </joint>
  <link
    name="Link4_L">
    <inertial>
      <origin
        xyz="0.00850411 -0.04718223 0.00941509"
        rpy="0 0 0" />
      <mass
        value="1.6085" />
      <inertia
        ixx="0.00580480"
        ixy="-0.00066669"
        ixz="-0.00012722"
        iyy="0.00223807"
        iyz="0.00070523"
        izz="0.00533060" />
    </inertial>
    <visual>
      <origin
        xyz="0 0 0"
        rpy="0 0 0" />
      <geometry>
        <mesh
          filename="package://Marvin M6-S-L-CCS-696-V4.0_URDF/meshes/Link4_L.STL" />
      </geometry>
      <material
        name="">
        <color
          rgba="0 1 0 1" />
      </material>
    </visual>
    <collision>
      <origin
        xyz="0 0 0"
        rpy="0 0 0" />
      <geometry>
        <mesh
          filename="package://Marvin M6-S-L-CCS-696-V4.0_URDF/meshes/Link4_L.STL" />
      </geometry>
    </collision>
  </link>
  <joint
    name="Joint4_L"
    type="revolute">
    <origin
      xyz="0.018 0 0"
      rpy="-1.5708 0 3.1416" />
    <parent
      link="Link3_L" />
    <child
      link="Link4_L" />
    <axis
      xyz="0 0 1" />
    <limit
      lower="-2.5307"
      upper="1.0472"
      effort="66"
      velocity="3.1416" />
  </joint>
  <link
    name="Link5_L">
    <inertial>
      <origin
        xyz="0.00051127 0.00101064 -0.11271739"
        rpy="0 0 0" />
      <mass
        value="2.0883" />
      <inertia
        ixx="0.00626603"
        ixy="0.00004009"
        ixz="0.00005338"
        iyy="0.00564387"
        iyz="-0.00006193"
        izz="0.00243632" />
    </inertial>
    <visual>
      <origin
        xyz="0 0 0"
        rpy="0 0 0" />
      <geometry>
        <mesh
          filename="package://Marvin M6-S-L-CCS-696-V4.0_URDF/meshes/Link5_L.STL" />
      </geometry>
      <material
        name="">
        <color
          rgba="0 0 1 1" />
      </material>
    </visual>
    <collision>
      <origin
        xyz="0 0 0"
        rpy="0 0 0" />
      <geometry>
        <mesh
          filename="package://Marvin M6-S-L-CCS-696-V4.0_URDF/meshes/Link5_L.STL" />
      </geometry>
    </collision>
  </link>
  <joint
    name="Joint5_L"
    type="revolute">
    <origin
      xyz="0.018 -0.314 0"
      rpy="-1.5708 0 3.1416" />
    <parent
      link="Link4_L" />
    <child
      link="Link5_L" />
    <axis
      xyz="0 0 1" />
    <limit
      lower="-3.1067"
      upper="3.1067"
      effort="18"
      velocity="3.1416" />
  </joint>
  <link
    name="Link6_L">
    <inertial>
      <origin
        xyz="0.00032659 0.00531336 -0.00030182"
        rpy="0 0 0" />
      <mass
        value="0.72496" />
      <inertia
        ixx="0.00046040"
        ixy="0.00000189"
        ixz="0.00000083"
        iyy="0.00051716"
        iyz="-0.00000346"
        izz="0.00042521" />
    </inertial>
    <visual>
      <origin
        xyz="0 0 0"
        rpy="0 0 0" />
      <geometry>
        <mesh
          filename="package://Marvin M6-S-L-CCS-696-V4.0_URDF/meshes/Link6_L.STL" />
      </geometry>
      <material
        name="">
        <color
          rgba="1 0 0 1" />
      </material>
    </visual>
    <collision>
      <origin
        xyz="0 0 0"
        rpy="0 0 0" />
      <geometry>
        <mesh
          filename="package://Marvin M6-S-L-CCS-696-V4.0_URDF/meshes/Link6_L.STL" />
      </geometry>
    </collision>
  </link>
  <joint
    name="Joint6_L"
    type="revolute">
    <origin
      xyz="0 0 0"
      rpy="1.5708 -1.5708 0" />
    <parent
      link="Link5_L" />
    <child
      link="Link6_L" />
    <axis
      xyz="0 0 1" />
    <limit
      lower="-1.0472"
      upper="1.0472"
      effort="18"
      velocity="3.1416" />
  </joint>
  <link
    name="Link7_L">
    <inertial>
      <origin
        xyz="-0.00009108 -0.03153255 0.00889371"
        rpy="0 0 0" />
      <mass
        value="0.68606" />
      <inertia
        ixx="0.00173687"
        ixy="-0.00000345"
        ixz="-0.00000116"
        iyy="0.00089035"
        iyz="0.00030680"
        izz="0.00139406" />
    </inertial>
    <visual>
      <origin
        xyz="0 0 0"
        rpy="0 0 0" />
      <geometry>
        <mesh
          filename="package://Marvin M6-S-L-CCS-696-V4.0_URDF/meshes/Link7_L.STL" />
      </geometry>
      <material
        name="">
        <color
          rgba="0 1 0 1" />
      </material>
    </visual>
    <collision>
      <origin
        xyz="0 0 0"
        rpy="0 0 0" />
      <geometry>
        <mesh
          filename="package://Marvin M6-S-L-CCS-696-V4.0_URDF/meshes/Link7_L.STL" />
      </geometry>
    </collision>
  </link>
  <joint
    name="Joint7_L"
    type="revolute">
    <origin
      xyz="0 0 0"
      rpy="1.5708 -1.5708 0" />
    <parent
      link="Link6_L" />
    <child
      link="Link7_L" />
    <axis
      xyz="0 0 1" />
    <limit
      lower="-1.5708"
      upper="1.5708"
      effort="18"
      velocity="3.1416" />
  </joint>
</robot>